{"nbformat":4,"nbformat_minor":0,"metadata":{"colab":{"provenance":[],"authorship_tag":"ABX9TyNX4h6bnANSeN+/7g524pVf"},"kernelspec":{"name":"python3","display_name":"Python 3"},"language_info":{"name":"python"}},"cells":[{"cell_type":"markdown","source":["Q1. Describe three applications for exception processing.\n","\n","Exception processing is a powerful feature of programming languages that allows developers to handle errors and unexpected situations in a structured and predictable way. Here are three applications for exception processing:\n","\n","1. Error handling: Exception processing is commonly used for error handling, where errors or exceptional conditions are identified and handled by the program in a consistent way. For example, if a file that a program is trying to read does not exist, an exception can be raised, and the program can catch the exception and display an error message to the user.\n","\n","2. Resource management: Exception processing can also be used for managing resources, such as files, network connections, or database connections. When working with resources, it's important to ensure that they are properly opened and closed, and that any errors that occur during the operation are handled gracefully. Exceptions can be used to ensure that resources are properly closed, even in the event of an error.\n","\n","3. Control flow: Exception processing can also be used for controlling the flow of a program. For example, a program may use an exception to signal that a particular condition has been met, and that the program should skip to a different part of the code. This can be useful for implementing complex logic, such as state machines or decision trees.\n","\n","In summary, exception processing is a versatile tool that can be used for error handling, resource management, and control flow in a wide range of programming applications. By handling exceptions in a consistent and predictable way, developers can create more reliable, robust, and maintainable software."],"metadata":{"id":"PyjoF_89NHy_"}},{"cell_type":"markdown","source":["Q2. What happens if you don't do something extra to treat an exception?\n","\n","If you don't handle an exception in your code, or if you don't do something extra to treat the exception, it will cause the program to terminate abruptly and display a traceback of the error message.\n","\n","When an exception is raised and not handled, the program execution stops immediately and the interpreter prints a message that includes the exception type, message, and the traceback. This traceback shows the sequence of function calls that lead up to the exception being raised, along with the line number where the exception occurred.\n","\n","For example, consider the following code:\n","\n","```\n","x = 5\n","y = 0\n","z = x / y\n","```\n","\n","In this code, we are trying to divide `x` by `y`, which will result in a ZeroDivisionError. If we don't handle the exception, the program will terminate with a traceback that looks something like this:\n","\n","```\n","Traceback (most recent call last):\n","  File \"<stdin>\", line 1, in <module>\n","ZeroDivisionError: division by zero\n","```\n","\n","This traceback shows that the exception occurred on line 3 of the code, where we tried to divide `x` by `y`, and it also shows the sequence of function calls that led up to the error.\n","\n","Therefore, it's important to handle exceptions in your code, either by using a try-except block to catch the exception and handle it appropriately, or by allowing the exception to propagate up the call stack to be handled by higher-level code. This can help to make your code more robust, reliable, and maintainable, and can prevent unexpected errors from causing your program to crash."],"metadata":{"id":"9D5RWnHFNe1z"}},{"cell_type":"markdown","source":["Q3. What are your options for recovering from an exception in your script?\n","\n","When an exception occurs in your script, there are several options for recovering from the exception and continuing with the execution of your code. Here are some of the most common strategies for recovering from exceptions:\n","\n","1. Catch and handle the exception: The most straightforward way to recover from an exception is to catch it and handle it in your code. You can do this using a try-except block, which allows you to execute a block of code and catch any exceptions that occur within that block. Once the exception is caught, you can take appropriate action, such as displaying an error message, logging the error, or retrying the operation.\n","\n","2. Retry the operation: Depending on the nature of the exception, it may be possible to recover by retrying the operation that caused the exception. For example, if a network operation fails due to a timeout, you may be able to recover by retrying the operation after a short delay. You can implement this strategy by using a loop that retries the operation until it succeeds, or until a maximum number of retries has been reached.\n","\n","3. Roll back the transaction: If the exception occurs during a transaction, such as a database update or a file write, it may be necessary to roll back the transaction to undo any changes that were made before the exception occurred. You can implement this strategy by using a try-except block to catch the exception and then rolling back the transaction in the except block.\n","\n","4. Graceful shutdown: If the exception is severe enough that the program cannot recover, it may be necessary to perform a graceful shutdown of the program. This can involve saving any unsaved data, closing any open resources, and displaying an appropriate error message to the user.\n","\n","In summary, there are several options for recovering from an exception in your script, including catching and handling the exception, retrying the operation, rolling back the transaction, and performing a graceful shutdown. The best strategy will depend on the nature of the exception and the specific requirements of your application."],"metadata":{"id":"MYnZoZsHOsjf"}},{"cell_type":"markdown","source":["Q4. Describe two methods for triggering exceptions in your script.\n","\n","There are several ways to trigger exceptions in a Python script, here are two methods:\n","\n","1. Raise an exception explicitly: You can raise an exception explicitly in your code by using the `raise` statement. This statement takes an exception object as its argument and raises the exception, which will interrupt the normal flow of your code and cause the exception to be propagated up the call stack. For example, you can raise a `ValueError` exception explicitly like this:\n","\n","```\n","x = -1\n","if x < 0:\n","    raise ValueError(\"x cannot be negative\")\n","```\n","\n","In this example, we check if the value of `x` is negative and raise a `ValueError` exception with a custom error message if it is. This will cause the program to terminate and display a traceback that shows where the exception was raised.\n","\n","2. Trigger an exception implicitly: In some cases, exceptions may be triggered implicitly by the Python interpreter or by external libraries. For example, if you try to access a non-existent dictionary key, Python will raise a `KeyError` exception. Similarly, if you try to divide a number by zero, Python will raise a `ZeroDivisionError` exception. Here's an example of how an implicit exception can be triggered:\n","\n","```\n","my_dict = {'a': 1, 'b': 2}\n","value = my_dict['c']\n","```\n","\n","In this example, we try to access the key `'c'` in the `my_dict` dictionary, which does not exist. This will trigger a `KeyError` exception, which will be propagated up the call stack and cause the program to terminate if not handled properly.\n","\n","In summary, you can trigger exceptions in your Python script by raising them explicitly using the `raise` statement or by triggering them implicitly through various operations or interactions with external libraries. It's important to handle these exceptions appropriately to ensure that your program runs smoothly and does not terminate unexpectedly."],"metadata":{"id":"nvous7krPLCl"}},{"cell_type":"markdown","source":["Q5. Identify two methods for specifying actions to be executed at termination time, regardless of whether or not an exception exists.\n","\n","In Python, there are two methods for specifying actions to be executed at termination time, regardless of whether or not an exception exists:\n","\n","1. Using `try-finally` block: The `try-finally` block allows you to specify a block of code that will always be executed, regardless of whether or not an exception occurs. The code in the `finally` block will be executed even if an exception is raised in the `try` block, which makes it useful for cleaning up resources, such as closing files or database connections. Here is an example:\n","\n","```\n","try:\n","    # code that may raise an exception\n","finally:\n","    # code that will always be executed\n","```\n","\n","In this example, the code in the `try` block may raise an exception, but the code in the `finally` block will always be executed, even if an exception occurs. This ensures that any resources opened in the `try` block are properly closed, regardless of whether or not an exception occurs.\n","\n","2. Using `atexit` module: The `atexit` module provides a simple way to register functions to be called when the Python interpreter is about to exit, either normally or due to an unhandled exception. This module provides the `register()` function, which takes a callable as its argument and registers it to be called when the interpreter is about to exit. Here is an example:\n","\n","```\n","import atexit\n","\n","def cleanup():\n","    # code to be executed at termination time\n","    pass\n","\n","atexit.register(cleanup)\n","```\n","\n","In this example, the `cleanup()` function is registered with the `atexit` module using the `register()` function. This function will be called automatically when the Python interpreter is about to exit, regardless of whether or not an exception occurs.\n","\n","In summary, the `try-finally` block and the `atexit` module provide two methods for specifying actions to be executed at termination time, regardless of whether or not an exception exists. The `try-finally` block is useful for cleaning up resources opened in a `try` block, while the `atexit` module is useful for registering functions to be called when the interpreter is about to exit."],"metadata":{"id":"ngTjW_Z-SH2-"}}]}