{"nbformat":4,"nbformat_minor":0,"metadata":{"colab":{"provenance":[],"authorship_tag":"ABX9TyPB+Bly4iYBmv1qD6Ol62N/"},"kernelspec":{"name":"python3","display_name":"Python 3"},"language_info":{"name":"python"}},"cells":[{"cell_type":"markdown","source":["Q1. What is the purpose of the try statement?\n","\n","The `try` statement in Python is used for exception handling. It allows you to write code that can potentially raise an exception, and specify what should happen when an exception occurs. The purpose of the `try` statement is to provide a way to handle exceptions that may occur during the execution of your code, without causing your program to crash or terminate unexpectedly.\n","\n","The `try` statement works by enclosing a block of code that may raise an exception in a `try` block, followed by one or more `except` blocks that specify how to handle specific types of exceptions. If an exception occurs in the `try` block, the interpreter will search for an `except` block that matches the type of the exception, and execute the code in that block. If no matching `except` block is found, the exception will be propagated up the call stack until it is caught by an outer `try` statement or causes the program to terminate if it is not caught.\n","\n","Here is an example of how the `try` statement can be used:\n","\n","```\n","try:\n","    # code that may raise an exception\n","    x = int(input(\"Enter a number: \"))\n","    y = 10 / x\n","    print(\"The result is:\", y)\n","except ValueError:\n","    # handle a value error\n","    print(\"Invalid input. Please enter a number.\")\n","except ZeroDivisionError:\n","    # handle a zero division error\n","    print(\"Cannot divide by zero.\")\n","```\n","\n","In this example, the `try` block contains code that reads a number from the user, performs a calculation, and prints the result. If an exception occurs, such as a `ValueError` or `ZeroDivisionError`, the corresponding `except` block is executed to handle the exception appropriately.\n","\n","In summary, the `try` statement in Python is used for exception handling, allowing you to write code that can handle errors and prevent your program from crashing or terminating unexpectedly."],"metadata":{"id":"MSoC1Q-ITWzO"}},{"cell_type":"markdown","source":["Q2. What are the two most popular try statement variations?\n","\n","The two most popular variations of the `try` statement in Python are the `try-except` statement and the `try-finally` statement.\n","\n","1. `try-except` statement: This variation allows you to catch and handle specific exceptions that may occur in the `try` block. It consists of a `try` block followed by one or more `except` blocks that specify how to handle specific types of exceptions. Here's an example:\n","\n","```\n","try:\n","    # code that may raise an exception\n","    x = int(input(\"Enter a number: \"))\n","    y = 10 / x\n","    print(\"The result is:\", y)\n","except ValueError:\n","    # handle a value error\n","    print(\"Invalid input. Please enter a number.\")\n","except ZeroDivisionError:\n","    # handle a zero division error\n","    print(\"Cannot divide by zero.\")\n","```\n","\n","In this example, the `try` block contains code that may raise exceptions, and there are two `except` blocks that handle specific types of exceptions (`ValueError` and `ZeroDivisionError`).\n","\n","2. `try-finally` statement: This variation allows you to ensure that some code is executed regardless of whether an exception occurs or not. It consists of a `try` block followed by a `finally` block that contains the code that should always be executed, regardless of whether an exception occurs or not. Here's an example:\n","\n","```\n","try:\n","    # code that may raise an exception\n","    x = int(input(\"Enter a number: \"))\n","    y = 10 / x\n","    print(\"The result is:\", y)\n","finally:\n","    # code that will always be executed\n","    print(\"This will always be printed.\")\n","```\n","\n","In this example, the `finally` block contains code that will always be executed, regardless of whether an exception occurs or not.\n","\n","In summary, the `try-except` and `try-finally` statements are the two most popular variations of the `try` statement in Python. The `try-except` statement is used for handling specific exceptions that may occur in the `try` block, while the `try-finally` statement is used for ensuring that some code is executed regardless of whether an exception occurs or not."],"metadata":{"id":"1ixyUNjWTzV8"}},{"cell_type":"markdown","source":["Q3. What is the purpose of the raise statement?\n","\n","The `raise` statement in programming is used to manually trigger an exception in Python. It is used to signal that an error or exceptional condition has occurred in the program and that the normal flow of execution cannot continue.\n","\n","The `raise` statement takes an exception type or instance as an argument. When the `raise` statement is executed, it creates an exception object of the specified type or instance and raises it. The exception then propagates up the call stack until it is caught by an appropriate exception handler, or until it reaches the top level of the program and causes the program to terminate.\n","\n","Here's an example of how the `raise` statement can be used to raise an exception:\n","\n","```python\n","def divide(x, y):\n","    if y == 0:\n","        raise ZeroDivisionError(\"Cannot divide by zero\")\n","    else:\n","        return x / y\n","\n","try:\n","    result = divide(10, 0)\n","except ZeroDivisionError as e:\n","    print(e) # Output: \"Cannot divide by zero\"\n","```\n","\n","In this example, the `divide()` function raises a `ZeroDivisionError` exception if the second argument `y` is equal to zero. The exception is caught by the `try`/`except` block, and the error message \"Cannot divide by zero\" is printed to the console."],"metadata":{"id":"gwnvRTvJVhP2"}},{"cell_type":"markdown","source":["Q4. What does the assert statement do, and what other statement is it like?\n","\n","The `assert` statement in Python is a debugging aid that tests a condition, and triggers an `AssertionError` if the condition is not true. It is typically used during development to catch bugs and ensure that certain assumptions are true at specific points in the code.\n","\n","The `assert` statement takes an expression and an optional error message as arguments. If the expression evaluates to `True`, the `assert` statement does nothing and the program continues execution. However, if the expression evaluates to `False`, the `assert` statement raises an `AssertionError` with the optional error message.\n","\n","Here's an example of how the `assert` statement can be used:\n","\n","```python\n","def divide(x, y):\n","    assert y != 0, \"Cannot divide by zero\"\n","    return x / y\n","\n","result = divide(10, 0)\n","```\n","\n","In this example, the `divide()` function uses an `assert` statement to check that the second argument `y` is not equal to zero before dividing `x` by `y`. If `y` is equal to zero, the `assert` statement raises an `AssertionError` with the message \"Cannot divide by zero\". This helps to catch the error early during development and make debugging easier.\n","\n","The `assert` statement is similar to the `if` statement, as both can be used to test conditions and control the flow of execution based on the results of the test. However, the main difference between the two is that `assert` is used for debugging and testing assumptions, while `if` is used for more general control flow and logic in a program."],"metadata":{"id":"4l9c-aZdV5EX"}},{"cell_type":"markdown","source":["Q5. What is the purpose of the with/as argument, and what other statement is it like?\n","\n","The `with` statement in Python provides a way to simplify the management of resources, such as files or network sockets, by ensuring that they are properly opened and closed. The `with` statement takes an object that supports the context management protocol and creates a context in which the object is valid.\n","\n","The `with` statement is typically used with the `as` keyword to assign the result of the object's `__enter__()` method to a variable. This variable can then be used within the `with` block, and the `__exit__()` method of the object is automatically called when the block is exited, even if an exception is raised.\n","\n","Here's an example of how the `with` statement can be used to open and read a file:\n","\n","```python\n","with open('example.txt') as file:\n","    contents = file.read()\n","    print(contents)\n","```\n","\n","In this example, the `with` statement opens the file `'example.txt'` and assigns the resulting file object to the variable `file`. The `read()` method is called on the file object to read its contents into the variable `contents`. Once the block is exited, the file is automatically closed by calling its `__exit__()` method.\n","\n","The `with` statement is similar to the `try`/`finally` statement in that it ensures that resources are properly cleaned up, but the `with` statement provides a more concise and readable syntax for achieving this goal.\n","\n","Here's an example of how the `try`/`finally` statement can be used to achieve the same result as the previous example:\n","\n","```python\n","file = open('example.txt')\n","try:\n","    contents = file.read()\n","    print(contents)\n","finally:\n","    file.close()\n","```\n","\n","In this example, the `try` block reads the contents of the file, and the `finally` block ensures that the file is closed, even if an exception is raised in the `try` block. However, the `with` statement provides a more concise and readable syntax for achieving the same goal."],"metadata":{"id":"9TldhadUWgHt"}}]}